<?xml version="1.0" encoding="utf-8"?>
<!-- This URDF was automatically created by SolidWorks to URDF Exporter! Originally created by Stephen Brawner (brawner@gmail.com) 
     Commit Version: 1.6.0-1-g15f4949  Build Version: 1.6.7594.29634
     For more information, please see http://wiki.ros.org/sw_urdf_exporter -->
<robot
  name="brazo" xmlns:xacro="http://www.ros.org/wiki/xacro">
  <link
    name="base_link">
    <inertial>
      <origin
        xyz="-8.9927E-18 0.082909 4.4771E-20"
        rpy="0 0 0" />
      <mass
        value="3.2518" />
      <inertia
        ixx="0.017546"
        ixy="-1.8589E-18"
        ixz="-8.2104E-19"
        iyy="0.010844"
        iyz="3.5287E-20"
        izz="0.017546" />
    </inertial>
    <visual>
      <origin
        xyz="0 0 0"
        rpy="0 0 0" />
      <geometry>
        <mesh
          filename="package://brazo/meshes/base_link.STL" />
      </geometry>
      <material
        name="">
        <color
          rgba="0 0 0 1" />
      </material>
    </visual>
    <collision>
      <origin
        xyz="0 0 0"
        rpy="0 0 0" />
      <geometry>
        <mesh
          filename="package://brazo/meshes/base_link.STL" />
      </geometry>
    </collision>
  </link>
   <link name="world" />
   <joint name="world_to_base_link=" type="fixed">
     <parent link="world"/>
     <child link="base_link"/>
  </joint>
  <link
    name="link1">
    <inertial>
      <origin
        xyz="6.2597E-09 0.17473 -0.00017925"
        rpy="0 0 0" />
      <mass
        value="1.3146" />
      <inertia
        ixx="0.012676"
        ixy="-1.1495E-12"
        ixz="9.8141E-10"
        iyy="0.00089209"
        iyz="2.9519E-05"
        izz="0.012621" />
    </inertial>
    <visual>
      <origin
        xyz="0 0 0"
        rpy="0 0 0" />
      <geometry>
        <mesh
          filename="package://brazo/meshes/link1.STL" />
      </geometry>
      <material
        name="">
        <color
          rgba="0 0 0 1" />
      </material>
    </visual>
    <collision>
      <origin
        xyz="0 0 0"
        rpy="0 0 0" />
      <geometry>
        <mesh
          filename="package://brazo/meshes/link1.STL" />
      </geometry>
    </collision>
  </link>
  <joint
    name="joint0"
    type="continuous">
    <origin
      xyz="0 0 0.19"
      rpy="1.5708 0 1.0057" />
    <parent
      link="base_link" />
    <child
      link="link1" />
    <axis
      xyz="0 1 0" />
  </joint>
  <link
    name="link2">
    <inertial>
      <origin
        xyz="0.10067 -0.12397 4.2501E-07"
        rpy="0 0 0" />
      <mass
        value="1.5823" />
      <inertia
        ixx="0.01719"
        ixy="0.00076596"
        ixz="-2.0766E-08"
        iyy="0.0014992"
        iyz="2.0301E-08"
        izz="0.017664" />
    </inertial>
    <visual>
      <origin
        xyz="0 0 0"
        rpy="0 0 0" />
      <geometry>
        <mesh
          filename="package://brazo/meshes/link2.STL" />
      </geometry>
      <material
        name="">
        <color
          rgba="0 0 0 1" />
      </material>
    </visual>
    <collision>
      <origin
        xyz="0 0 0"
        rpy="0 0 0" />
      <geometry>
        <mesh
          filename="package://brazo/meshes/link2.STL" />
      </geometry>
    </collision>
  </link>
  <joint
    name="joint1"
    type="continuous">
    <origin
      xyz="0 0.3 0"
      rpy="0.76644 -1.5708 0" />
    <parent
      link="link1" />
    <child
      link="link2" />
    <axis
      xyz="1 0 0" />
  </joint>
  <link
    name="link3">
    <inertial>
      <origin
        xyz="0.19781 -0.071987 -3.4353E-08"
        rpy="0 0 0" />
      <mass
        value="1.1233" />
      <inertia
        ixx="0.0063484"
        ixy="0.00046984"
        ixz="4.9051E-09"
        iyy="0.0010023"
        iyz="5.9339E-09"
        izz="0.006642" />
    </inertial>
    <visual>
      <origin
        xyz="0 0 0"
        rpy="0 0 0" />
      <geometry>
        <mesh
          filename="package://brazo/meshes/link3.STL" />
      </geometry>
      <material
        name="">
        <color
          rgba="0 0 0 1" />
      </material>
    </visual>
    <collision>
      <origin
        xyz="0 0 0"
        rpy="0 0 0" />
      <geometry>
        <mesh
          filename="package://brazo/meshes/link3.STL" />
      </geometry>
    </collision>
  </link>
  <joint
    name="joint2"
    type="continuous">
    <origin
      xyz="0.016377 -0.255 0"
      rpy="1.6749 0 0" />
    <parent
      link="link2" />
    <child
      link="link3" />
    <axis
      xyz="1 0 0" />
  </joint>
   <!-- ros_control plugin -->
    <gazebo>
        <plugin name="gazebo_ros_control" filename="libgazebo_ros_control.so">
            <robotNamespace>/brazo</robotNamespace>
            <robotSimType>gazebo_ros_control/DefaultRobotHWSim</robotSimType>
        </plugin>
    </gazebo>
    <gazebo reference="base_link">
        <material>Gazebo/Black</material>
    </gazebo>
    
<transmission name="tran1">
    <type>transmission_interface/SimpleTransmission</type>
    <joint name="joint0">
        <hardwareInterface>hardware_interface/EffortJointInterface</hardwareInterface>
    </joint>
    <actuator name="motor1">
        <hardwareInterface>hardware_interface/EffortJointInterface</hardwareInterface>
        <mechanicalReduction>1</mechanicalReduction>
    </actuator>
</transmission>

<transmission name="tran2">
    <type>transmission_interface/SimpleTransmission</type>
    <joint name="joint1">
        <hardwareInterface>hardware_interface/EffortJointInterface</hardwareInterface>
    </joint>
    <actuator name="motor2">
        <hardwareInterface>hardware_interface/EffortJointInterface</hardwareInterface>
        <mechanicalReduction>1</mechanicalReduction>
    </actuator>
</transmission>

<transmission name="tran3">
    <type>transmission_interface/SimpleTransmission</type>
    <joint name="joint2">
        <hardwareInterface>hardware_interface/EffortJointInterface</hardwareInterface>
    </joint>
    <actuator name="motor3">
        <hardwareInterface>hardware_interface/EffortJointInterface</hardwareInterface>
        <mechanicalReduction>1</mechanicalReduction>
    </actuator>
</transmission>
</robot>