<?xml version="1.0" encoding="utf-8"?>
<!-- This URDF was automatically created by SolidWorks to URDF Exporter! Originally created by Stephen Brawner (brawner@gmail.com) 
     Commit Version: 1.6.0-1-g15f4949  Build Version: 1.6.7594.29634
     For more information, please see http://wiki.ros.org/sw_urdf_exporter -->
<robot
  name="manipulator">
  <link
    name="base_link">
    <inertial>
      <origin
        xyz="-8.9967E-18 0.082909 3.663E-20"
        rpy="0 0 0" />
      <mass
        value="3.2518" />
      <inertia
        ixx="0.017546"
        ixy="-1.8589E-18"
        ixz="-8.2104E-19"
        iyy="0.010844"
        iyz="3.1978E-20"
        izz="0.017546" />
    </inertial>
    <visual>
      <origin
        xyz="0 0 0"
        rpy="0 0 0" />
      <geometry>
        <mesh
          filename="package://manipulator/meshes/base_link.STL" />
      </geometry>
      <material
        name="">
        <color
          rgba="0 0 0 1" />
      </material>
    </visual>
    <collision>
      <origin
        xyz="0 0 0"
        rpy="0 0 0" />
      <geometry>
        <mesh
          filename="package://manipulator/meshes/base_link.STL" />
      </geometry>
    </collision>
  </link>
  <link
    name="link1">
    <inertial>
      <origin
        xyz="6.2597E-09 0.17473 -0.00017925"
        rpy="0 0 0" />
      <mass
        value="1.3146" />
      <inertia
        ixx="0.012676"
        ixy="-1.1495E-12"
        ixz="9.8141E-10"
        iyy="0.00089209"
        iyz="2.9519E-05"
        izz="0.012621" />
    </inertial>
    <visual>
      <origin
        xyz="0 0 0"
        rpy="0 0 0" />
      <geometry>
        <mesh
          filename="package://manipulator/meshes/link1.STL" />
      </geometry>
      <material
        name="">
        <color
          rgba="0 0 0 1" />
      </material>
    </visual>
    <collision>
      <origin
        xyz="0 0 0"
        rpy="0 0 0" />
      <geometry>
        <mesh
          filename="package://manipulator/meshes/link1.STL" />
      </geometry>
    </collision>
  </link>
  <joint
    name="joint0"
    type="continuous">
    <origin
      xyz="0 0 0.19"
      rpy="1.5708 0 1.5708" />
    <parent
      link="base_link" />
    <child
      link="link1" />
    <axis
      xyz="0 1 0" />
  </joint>
  <link
    name="link2">
    <inertial>
      <origin
        xyz="0.090667 -0.12397 2.5675E-07"
        rpy="0 0 0" />
      <mass
        value="1.5823" />
      <inertia
        ixx="0.01719"
        ixy="0.00076592"
        ixz="3.3275E-10"
        iyy="0.0014992"
        iyz="2.4054E-09"
        izz="0.017664" />
    </inertial>
    <visual>
      <origin
        xyz="0 0 0"
        rpy="0 0 0" />
      <geometry>
        <mesh
          filename="package://manipulator/meshes/link2.STL" />
      </geometry>
      <material
        name="">
        <color
          rgba="0 0 0 1" />
      </material>
    </visual>
    <collision>
      <origin
        xyz="0 0 0"
        rpy="0 0 0" />
      <geometry>
        <mesh
          filename="package://manipulator/meshes/link2.STL" />
      </geometry>
    </collision>
  </link>
  <joint
    name="joint1"
    type="continuous">
    <origin
      xyz="0 0.3 0.01"
      rpy="0 -1.5708 0" />
    <parent
      link="link1" />
    <child
      link="link2" />
    <axis
      xyz="1 0 0" />
  </joint>
  <link
    name="link3">
    <inertial>
      <origin
        xyz="0.08919 -0.071986 3.5323E-08"
        rpy="0 0 0" />
      <mass
        value="1.1233" />
      <inertia
        ixx="0.0063484"
        ixy="0.00046983"
        ixz="-1.0835E-09"
        iyy="0.0010023"
        iyz="-5.3698E-10"
        izz="0.006642" />
    </inertial>
    <visual>
      <origin
        xyz="0 0 0"
        rpy="0 0 0" />
      <geometry>
        <mesh
          filename="package://manipulator/meshes/link3.STL" />
      </geometry>
      <material
        name="">
        <color
          rgba="0 0 0 1" />
      </material>
    </visual>
    <collision>
      <origin
        xyz="0 0 0"
        rpy="0 0 0" />
      <geometry>
        <mesh
          filename="package://manipulator/meshes/link3.STL" />
      </geometry>
    </collision>
  </link>
  <joint
    name="joint2"
    type="continuous">
    <origin
      xyz="0.115 -0.255 0"
      rpy="0 0 0" />
    <parent
      link="link2" />
    <child
      link="link3" />
    <axis
      xyz="1 0 0" />
  </joint>
</robot>